[2024-05-12T06:32:51.591+0000] {taskinstance.py:1159} INFO - Dependencies all met for dep_context=non-requeueable deps ti=<TaskInstance: crawl_dag.send_email manual__2024-05-12T06:27:49.071778+00:00 [queued]>
[2024-05-12T06:32:51.604+0000] {taskinstance.py:1159} INFO - Dependencies all met for dep_context=requeueable deps ti=<TaskInstance: crawl_dag.send_email manual__2024-05-12T06:27:49.071778+00:00 [queued]>
[2024-05-12T06:32:51.605+0000] {taskinstance.py:1361} INFO - Starting attempt 2 of 2
[2024-05-12T06:32:51.624+0000] {taskinstance.py:1382} INFO - Executing <Task(PythonOperator): send_email> on 2024-05-12 06:27:49.071778+00:00
[2024-05-12T06:32:51.629+0000] {standard_task_runner.py:57} INFO - Started process 263 to run task
[2024-05-12T06:32:51.632+0000] {standard_task_runner.py:84} INFO - Running: ['***', 'tasks', 'run', 'crawl_dag', 'send_email', 'manual__2024-05-12T06:27:49.071778+00:00', '--job-id', '327', '--raw', '--subdir', 'DAGS_FOLDER/demo.py', '--cfg-path', '/tmp/tmp6sg3145z']
[2024-05-12T06:32:51.635+0000] {standard_task_runner.py:85} INFO - Job 327: Subtask send_email
[2024-05-12T06:32:51.684+0000] {task_command.py:416} INFO - Running <TaskInstance: crawl_dag.send_email manual__2024-05-12T06:27:49.071778+00:00 [running]> on host 33d344986a85
[2024-05-12T06:32:51.773+0000] {taskinstance.py:1662} INFO - Exporting env vars: AIRFLOW_CTX_DAG_OWNER='thinhcute' AIRFLOW_CTX_DAG_ID='crawl_dag' AIRFLOW_CTX_TASK_ID='send_email' AIRFLOW_CTX_EXECUTION_DATE='2024-05-12T06:27:49.071778+00:00' AIRFLOW_CTX_TRY_NUMBER='2' AIRFLOW_CTX_DAG_RUN_ID='manual__2024-05-12T06:27:49.071778+00:00'
[2024-05-12T06:32:51.779+0000] {taskinstance.py:1937} ERROR - Task failed with exception
Traceback (most recent call last):
  File "/home/airflow/.local/lib/python3.8/site-packages/airflow/operators/python.py", line 192, in execute
    return_value = self.execute_callable()
  File "/home/airflow/.local/lib/python3.8/site-packages/airflow/operators/python.py", line 209, in execute_callable
    return self.python_callable(*self.op_args, **self.op_kwargs)
  File "/opt/airflow/dags/data_email.py", line 26, in email
    with open(out_csv_file_path,'rb') as f:
FileNotFoundError: [Errno 2] No such file or directory: '/opt/airflow/data/clean_data/2024/5/12/nguyenducthinh_fpt.json'
[2024-05-12T06:32:51.799+0000] {taskinstance.py:1400} INFO - Marking task as FAILED. dag_id=crawl_dag, task_id=send_email, execution_date=20240512T062749, start_date=20240512T063251, end_date=20240512T063251
[2024-05-12T06:32:51.809+0000] {standard_task_runner.py:104} ERROR - Failed to execute job 327 for task send_email ([Errno 2] No such file or directory: '/opt/airflow/data/clean_data/2024/5/12/nguyenducthinh_fpt.json'; 263)
[2024-05-12T06:32:51.846+0000] {local_task_job_runner.py:228} INFO - Task exited with return code 1
[2024-05-12T06:32:51.861+0000] {taskinstance.py:2778} INFO - 0 downstream tasks scheduled from follow-on schedule check
